#VRML_SIM R2025a utf8

EXTERNPROTO "https://raw.githubusercontent.com/cyberbotics/webots/R2025a/projects/objects/backgrounds/protos/TexturedBackground.proto"
EXTERNPROTO "https://raw.githubusercontent.com/cyberbotics/webots/R2025a/projects/objects/backgrounds/protos/TexturedBackgroundLight.proto"
EXTERNPROTO "https://raw.githubusercontent.com/cyberbotics/webots/R2025a/projects/objects/floors/protos/RectangleArena.proto"
EXTERNPROTO "https://raw.githubusercontent.com/cyberbotics/webots/R2025a/projects/appearances/protos/Plastic.proto"
EXTERNPROTO "https://raw.githubusercontent.com/cyberbotics/webots/R2025a/projects/objects/shapes/protos/TexturedBoxShape.proto"

WorldInfo {
}
Viewpoint {
  orientation 0.014552262379763422 0.9910204767616078 -0.13291593696327794 0.37361396226244087
  position -6.476741125020309 5.869906303878429 1.677780958527649
}
TexturedBackground {
}
TexturedBackgroundLight {
}
RectangleArena {
  floorSize 1000 1000
  floorAppearance Plastic {
  }
}
TexturedBoxShape {
  size 5 0.05 0.01
  textureMapping "metric"
  faceColor 0 0 0
  frontFace FALSE
  backFace FALSE
  leftFace FALSE
  rightFace FALSE
  topFace FALSE
  bottomFace FALSE
}
Pose {
  translation -3.944e-06 5.67 0.0100061
  rotation 0.577349935856137 0.5773509358560258 -0.577349935856137 -2.094395307179586
  children [
    CadShape {
      url [
        "../../TeenSizeAcrylic/Arena/track.obj"
      ]
    }
  ]
}
Robot {
  translation -2.774826761482883 4.996602705159283 0.5701103788175642
  rotation -0.06500789060865955 0.04078687314594091 0.9970508538372502 2.0224501231661445
  children [
    InertialUnit {
      name "InertialUnit"
    }
    DEF BODY_SLOT Group {
    }
    Pose {
      rotation 0.577416935887098 0.5773169329539689 0.5773169329539689 2.0944
      children [
        DEF JERSEY_SLOT Slot {
          type "robotis jersey"
        }
      ]
    }
    Pose {
      rotation 0.577416935887098 0.5773169329539689 0.5773169329539689 2.0944
      children [
        DEF DBodyShape Pose {
          translation 0.233 -0.1123 -0.0081
          children [
            CadShape {
              url [
                "../../TeenSizeAcrylic/Webots3d/BodyAssembly.obj"
              ]
            }
          ]
        }
      ]
    }
    LED {
      translation -0.043 -0.00500339 -0.0100018
      rotation 0.577416935887098 0.5773169329539689 0.5773169329539689 2.0944
      children [
        Shape {
          appearance PBRAppearance {
            transparency 0.1
            roughness 0.3
            metalness 0
            emissiveIntensity 6
          }
          geometry Box {
            size 0.002 0.005 0.002
          }
        }
      ]
      name "BackLedGreen"
      color [
        0 1 0
      ]
    }
    LED {
      translation -0.043 0 -0.01
      rotation 0.577416935887098 0.5773169329539689 0.5773169329539689 2.0944
      children [
        Shape {
          appearance PBRAppearance {
            transparency 0.1
            roughness 0.3
            metalness 0
            emissiveIntensity 6
          }
          geometry Box {
            size 0.002 0.005 0.002
          }
        }
      ]
      name "BackLedBlue"
      color [
        0 0 1
      ]
    }
    LED {
      translation -0.043 0.005 -0.01
      rotation 0.577416935887098 0.5773169329539689 0.5773169329539689 2.0944
      children [
        Shape {
          appearance PBRAppearance {
            roughness 0.2
            metalness 0
          }
          geometry Box {
            size 0.002 0.005 0.002
          }
        }
      ]
      name "BackLedRed"
    }
    Speaker {
      translation 0.2 0 0
      rotation -0.9831126183314349 0.12940166088097618 -0.12940166088097618 -1.5878
      name "Speaker"
    }
    Accelerometer {
      translation -0.01 0 -0.108
      rotation 0 0 1 -1.5708
      name "Accelerometer"
      lookupTable [
        -39.24 0 0
        39.24 1024 0
      ]
    }
    Gyro {
      translation 0.01 0 -0.108
      rotation 0 0 1 -3.1416
      name "Gyro"
      lookupTable [
        -27.925 0 0
        27.925 1024 0
      ]
    }
    DEF RECEIVER Receiver {
      rotation 0.577416935887098 0.5773169329539689 0.5773169329539689 2.0944
    }
    DEF EMITTER Emitter {
      rotation 0.577416935887098 0.5773169329539689 0.5773169329539689 2.0944
    }
    DEF SUPER_EMITTER Emitter {
      rotation 0.577416935887098 0.5773169329539689 0.5773169329539689 2.0944
      name "super_emitter"
      channel 2
    }
    DEF DNeck HingeJoint {
      jointParameters HingeJointParameters {
        position -6.658185414178056e-12
        axis 0 0 1
        anchor 0.0004 0.0001 0
        dampingConstant 0.002
        staticFriction 0.025
      }
      device [
        RotationalMotor {
          name "Neck"
          acceleration 55
          maxVelocity 12.26
          minPosition -1.81
          maxPosition 1.81
          maxTorque 2.5
        }
        PositionSensor {
          name "NeckS"
        }
      ]
      endPoint Solid {
        translation 3.931253125767295e-09 -4.744683461497135e-11 0.0509990831920165
        rotation 0.5774169053403665 0.5773169568127848 0.5773169396471743 2.0944000639254536
        children [
          DEF DNeckShape Pose {
            translation 0.00905 0.0256 -0.01215
            children [
              CadShape {
                url [
                  "../../TeenSizeAcrylic/Webots3d/Neck.obj"
                ]
              }
            ]
          }
          DEF DHead HingeJoint {
            jointParameters HingeJointParameters {
              position -0.6000000001711466
              axis -1 0 0
              anchor 0 0.0427 0.0003
              dampingConstant 0.002
              staticFriction 0.025
            }
            device [
              RotationalMotor {
                name "Head"
                acceleration 55
                maxVelocity 12.26
                minPosition -1
                maxPosition 0.94
                maxTorque 2.5
              }
              PositionSensor {
                name "HeadS"
              }
            ]
            endPoint Solid {
              translation 0.005269999999999793 0.04092991184567553 -0.00012342405424627486
              rotation 1 0 0 0.600000000171147
              children [
                DEF HEAD_SLOT Pose {
                  translation 0 0.022 -0.012
                }
                DEF DHeadShape Group {
                  children [
                    Shape {
                      appearance DEF PUPIL_APPEARANCE PBRAppearance {
                        baseColor 0.05 0.05 0.05
                        transparency 1
                        metalness 0
                      }
                      geometry IndexedFaceSet {
                        coord DEF DHeadCoord Coordinate {
                          point [
                            0.0392305 0.0221018 -0.0570645, -0.0392305 0.0221018 -0.0570645, 0.0405922 0.0152099 -0.0401748, -0.0405922 0.0152099 -0.0401748, 0.0411355 0.0081425 -0.0334363, -0.0411355 0.0081425 -0.0334363, 0.0416294 -0.0007687 -0.0273103, -0.0416294 -0.0007687 -0.0273103, 0.0424073 -0.0072215 -0.0176621, -0.0424073 -0.0072215 -0.0176621, 0.0433401 -0.0086732 -0.0060919, -0.0433401 -0.0086732 -0.0060919, 0.044197 -0.0061456 0.0045363, -0.044197 -0.0061456 0.0045363, 0.0449545 0.0006532 0.0139317, -0.0449545 0.0006532 0.0139317, 0.0452514 0.0108622 0.0176143, -0.0452514 0.0108622 0.0176143, 0.0452514 0.0212564 0.0176141, -0.0452514 0.0212564 0.0176141, 0.0449057 0.0300627 0.0137528, -0.0449057 0.0300627 0.0137528, 0.0442507 0.0353979 0.0052024, -0.0442507 0.0353979 0.0052024, 0.0433849 0.0381032 -0.0055372, -0.0433849 0.0381032 -0.0055372, 0.038476 0.0363362 -0.0664233, -0.038476 0.0363362 -0.0664233, 0.0116412 0.0265999 0.0366955, -0.0116412 0.0265999 0.0366955, 0.0152554 0.0218632 0.0363648, -0.0152554 0.0218632 0.0363648, 0.0201309 0.0187384 0.0349243, -0.0201309 0.0187384 0.0349243, 0.0255253 0.0177015 0.0325931, -0.0255253 0.0177015 0.0325931, 0.0306174 0.0189101 0.0297263, -0.0306174 0.0189101 0.0297263, 0.034632 0.0221804 0.0267603, -0.034632 0.0221804 0.0267603, 0.0369579 0.0270145 0.0241466, -0.0369579 0.0270145 0.0241466, 0.037241 0.0326763 0.0222832, -0.037241 0.0326763 0.0222832, 0.0354382 0.038304 0.0214537, -0.0354382 0.038304 0.0214537, 0.0318239 0.0430408 0.0217844, -0.0318239 0.0430408 0.0217844, 0.0269485 0.0461655 0.023225, -0.0269485 0.0461655 0.023225, 0.0215541 0.0472024 0.0255561, -0.0215541 0.0472024 0.0255561, 0.016462 0.0459938 0.0284229, -0.016462 0.0459938 0.0284229, 0.0124474 0.0427235 0.0313889, -0.0124474 0.0427235 0.0313889, 0.0101215 0.0378894 0.0340026, -0.0101215 0.0378894 0.0340026, 0.0098384 0.0322276 0.035866, -0.0098384 0.0322276 0.035866, 0.0174415 0.0294527 0.0329804, -0.0174415 0.0294527 0.0329804, 0.0192939 0.0270251 0.032811, -0.0192939 0.0270251 0.032811, 0.0217926 0.0254236 0.0320726, -0.0217926 0.0254236 0.0320726, 0.0245573 0.0248921 0.0308779, -0.0245573 0.0248921 0.0308779, 0.0271671 0.0255116 0.0294086, -0.0271671 0.0255116 0.0294086, 0.0292247 0.0271877 0.0278885, -0.0292247 0.0271877 0.0278885, 0.0304167 0.0296652 0.026549, -0.0304167 0.0296652 0.026549, 0.0305618 0.0325669 0.0255939, -0.0305618 0.0325669 0.0255939, 0.0296378 0.0354512 0.0251688, -0.0296378 0.0354512 0.0251688, 0.0277855 0.0378789 0.0253383, -0.0277855 0.0378789 0.0253383, 0.0252868 0.0394803 0.0260766, -0.0252868 0.0394803 0.0260766, 0.022522 0.0400118 0.0272713, -0.022522 0.0400118 0.0272713, 0.0199123 0.0393923 0.0287406, -0.0199123 0.0393923 0.0287406, 0.0178547 0.0377163 0.0302607, -0.0178547 0.0377163 0.0302607, 0.0166627 0.0352387 0.0316003, -0.0166627 0.0352387 0.0316003, 0.0165176 0.032337 0.0325553, -0.0165176 0.032337 0.0325553, 0.0235397 0.032452 0.0290746, -0.0235397 0.032452 0.0290746, 0.0195178 0.0464315 -0.0795508, -0.0195178 0.0464315 -0.0795508, 0.0225675 0.0325759 -0.07354, -0.0225675 0.0325759 -0.07354, 0.0195174 0.016289 -0.0574006, -0.0195174 0.016289 -0.0574006, 0.0186086 0.0055227 -0.0552789, -0.0186086 0.0055227 -0.0552789, 0.0184255 -0.0009917 -0.051584, -0.0184255 -0.0009917 -0.051584, 0.0186973 -0.0121609 -0.0394498, -0.0186973 -0.0121609 -0.0394498, 0.0207908 -0.0194756 -0.0266185, -0.0207908 -0.0194756 -0.0266185, 0.0185759 -0.0211818 -0.014516, -0.0185759 -0.0211818 -0.014516, 0.0186379 -0.0196935 -0.001655, -0.0186379 -0.0196935 -0.001655, 0.0187539 -0.0135358 0.0128219, -0.0187539 -0.0135358 0.0128219, 0.018584 -0.0050813 0.024037, -0.018584 -0.0050813 0.024037, 0.0164893 0.0066883 0.0349741, -0.0164893 0.0066883 0.0349741, 0.0165623 0.0155422 0.0362219, -0.0165623 0.0155422 0.0362219, 0.0170276 0.0499737 0.0249869, -0.0170276 0.0499737 0.0249869, 0.01726 0.0553882 0.0150497, -0.01726 0.0553882 0.0150497, 0.0120454 0.0605195 0.0046781, -0.0120454 0.0605195 0.0046781, 0.0181589 0.0602533 -0.0062721, -0.0181589 0.0602533 -0.0062721, 0.0195168 0.060201 -0.0189165, -0.0195168 0.060201 -0.0189165, 0.0195174 0.0540533 -0.0540891, -0.0195174 0.0540533 -0.0540891, 0 -0.0138808 -0.0402319, 0 -0.0213466 -0.0278119, 0 -0.0227678 -0.0144287, 0 -0.022019 -1.81e-05, 0 -0.0156556 0.0154359, 0 -0.0061624 0.0265574, 0 0.0074755 0.0378864, 0 0.0175306 0.0379284, 0 0.032467 0.0361502, 0 0.0381629 0.0344413, 0 0.045242 0.0309423, 0 0.0488546 0.0285779, 0 0.057406 0.0180599, 0 0.0609716 0.0107532, 0 0.060921 -0.0062633, 0 0.0608675 -0.0189168, 0 0.051912 -0.0393596, 0 0.0386829 -0.0524273, 0.0195171 0.0508041 -0.0384949, -0.0195171 0.0508041 -0.0384949, 0.0195173 0.0380376 -0.0514338, -0.0195173 0.0380376 -0.0514338, 0 0.0161334 -0.0593111, 0 0.004431 -0.0571641, 0 -0.0022158 -0.0534247, 0.0291343 0.0417313 -0.0729934, -0.0291343 0.0417313 -0.0729934, 0.0304317 0.0350942 -0.0702807, -0.0304317 0.0350942 -0.0702807, 0.0297588 0.0190742 -0.0580713, -0.0297588 0.0190742 -0.0580713, 0.031687 0.0160369 -0.0526305, -0.031687 0.0160369 -0.0526305, 0.0309837 0.0092284 -0.0486846, -0.0309837 0.0092284 -0.0486846, 0.030947 0.0028528 -0.0442747, -0.030947 0.0028528 -0.0442747, 0.0313671 -0.0070052 -0.0342981, -0.0313671 -0.0070052 -0.0342981, 0.0327293 -0.0142829 -0.0243646, -0.0327293 -0.0142829 -0.0243646, 0.0320906 -0.0174994 -0.0152496, -0.0320906 -0.0174994 -0.0152496, 0.0334606 -0.0171215 -0.0025047, -0.0334606 -0.0171215 -0.0025047, 0.0348758 -0.0119176 0.010511, -0.0348758 -0.0119176 0.010511, 0.0352073 -0.0039472 0.0212155, -0.0352073 -0.0039472 0.0212155, 0.0303691 0.0014046 0.0276174, -0.0303691 0.0014046 0.0276174, 0.0331355 0.0159014 0.0280857, -0.0331355 0.0159014 0.0280857, 0.033055 0.0441668 0.018925, -0.033055 0.0441668 0.018925, 0.0272452 0.0520301 0.0117203, -0.0272452 0.0520301 0.0117203, 0.0274988 0.054967 0.0026082, -0.0274988 0.054967 0.0026082, 0.0273044 0.0556295 -0.0065691, -0.0273044 0.0556295 -0.0065691, 0.0276693 0.0543365 -0.0244786, -0.0276693 0.0543365 -0.0244786, 0.0323266 0.0444186 -0.0491837, -0.0323266 0.0444186 -0.0491837, 0.0417486 0.0375142 -0.0258325, -0.0417486 0.0375142 -0.0258325, 0.0401123 0.0369252 -0.0461279, -0.0401123 0.0369252 -0.0461279, 0.0070464 0.0573781 0.01728, -0.0070464 0.0573781 0.01728, 0.0083894 0.0559858 0.019199, -0.0083894 0.0559858 0.019199, 0.008978 0.0540208 0.0218855, -0.008978 0.0540208 0.0218855, 0.0049843 0.051013 0.0258813, -0.0049843 0.051013 0.0258813, 0.0381348 0.039614 0.0149968, -0.0381348 0.039614 0.0149968, 0.0374798 0.0437726 0.0079673, -0.0374798 0.0437726 0.0079673, 0.0368872 0.0477009 -0.0022339, -0.0368872 0.0477009 -0.0022339, 0.0349777 0.0463099 -0.0278206, -0.0349777 0.0463099 -0.0278206, 0 0.0572104 -0.0285718, 0 0.0462024 -0.0462686, 0.0195172 0.0456088 -0.0455197, -0.0195172 0.0456088 -0.0455197, 0.0195174 0.0280225 -0.056562, -0.0195174 0.0280225 -0.056562, 0 0.0286387 -0.0571265, 0.0195169 0.0566908 -0.0283183, -0.0195169 0.0566908 -0.0283183
                          ]
                        }
                        coordIndex [
                          62, 92, 60, -1, 61, 93, 63, -1, 64, 92, 62, -1, 63, 93, 65, -1, 66, 92, 64, -1, 65, 93, 67, -1, 68, 92, 66, -1, 67, 93, 69, -1, 70, 92, 68, -1, 69, 93, 71, -1, 72, 92, 70, -1, 71, 93, 73, -1, 74, 92, 72, -1, 73, 93, 75, -1, 76, 92, 74, -1, 75, 93, 77, -1, 78, 92, 76, -1, 77, 93, 79, -1, 80, 92, 78, -1, 79, 93, 81, -1, 82, 92, 80, -1, 81, 93, 83, -1, 84, 92, 82, -1, 83, 93, 85, -1, 86, 92, 84, -1, 85, 93, 87, -1, 88, 92, 86, -1, 87, 93, 89, -1, 90, 92, 88, -1, 89, 93, 91, -1, 60, 92, 90, -1, 91, 93, 61, -1
                        ]
                        creaseAngle 0.52
                      }
                    }
                    Pose {
                      translation 0.00378 -0.0154 -0.0131
                      children [
                        DEF DHeadCoord CadShape {
                          url [
                            "../../TeenSizeAcrylic/Webots3d/Head.obj"
                          ]
                        }
                      ]
                    }
                  ]
                }
                Camera {
                  translation -0.0050001 0.0299998 0.015
                  rotation 0.5773529358436793 0.5773529358436793 0.5773449358445683 -2.094395307179586
                  children [
                    DEF DCameraShape Shape {
                      appearance DEF DCameraAppearance PBRAppearance {
                        transparency 1
                        roughness 0.3
                        metalness 0
                      }
                      geometry IndexedFaceSet {
                        coord Coordinate {
                          point [
                            0.0016242 -0.0012902 0.0006454
                            0.0009796 -0.0012902 -0.0018532
                            0.0009796 0.0012902 -0.0018532
                            0.0016242 0.0012902 0.0006454
                            -0.0001212 -0.0030927 0.0010956
                            -0.0007657 -0.0030927 -0.001403
                            -0.001216 -0.0012902 -0.0031483
                            -0.001216 0.0012901 -0.0031484
                            -0.0007657 0.0030927 -0.001403
                            -0.0001212 0.0030927 0.0010956
                            0.0003291 -0.0012902 0.002841
                            0.0003291 0.0012902 0.002841
                          ]
                        }
                        coordIndex [
                          0, 10, 4, -1, 1, 5, 6, -1, 2, 7, 8, -1, 3, 9, 11, -1, 9, 3, 2, -1, 9, 2, 8, -1, 10, 0, 3, -1, 10, 3, 11, -1, 7, 2, 1, -1, 7, 1, 6, -1, 0, 4, 5, -1, 0, 5, 1, -1, 0, 1, 2, -1, 0, 2, 3, -1
                        ]
                        creaseAngle 0.2
                      }
                    }
                  ]
                  name "Camera"
                  fieldOfView 1.0123
                  width 160
                  height 120
                  zoom Zoom {
                  }
                }
                DEF DEyeLED LED {
                  rotation 1 0 0 0
                  children [
                    DEF DEyeLEDShape Shape {
                      appearance DEF DEyeLEDAppearance PBRAppearance {
                        baseColor 0.7 0.7 0.7
                        transparency 1
                        roughness 0.3
                        metalness 0
                        emissiveIntensity 6
                      }
                      geometry IndexedFaceSet {
                        coord Coordinate {
                          point [
                            0.0116412 0.0265999 0.0366955, -0.0116412 0.0265999 0.0366955, 0.0152554 0.0218632 0.0363648, -0.0152554 0.0218632 0.0363648, 0.0201309 0.0187384 0.0349243, -0.0201309 0.0187384 0.0349243, 0.0255253 0.0177015 0.0325931, -0.0255253 0.0177015 0.0325931, 0.0306174 0.0189101 0.0297263, -0.0306174 0.0189101 0.0297263, 0.034632 0.0221804 0.0267603, -0.034632 0.0221804 0.0267603, 0.0369579 0.0270145 0.0241466, -0.0369579 0.0270145 0.0241466, 0.037241 0.0326763 0.0222832, -0.037241 0.0326763 0.0222832, 0.0354382 0.038304 0.0214537, -0.0354382 0.038304 0.0214537, 0.0318239 0.0430408 0.0217844, -0.0318239 0.0430408 0.0217844, 0.0269485 0.0461655 0.023225, -0.0269485 0.0461655 0.023225, 0.0215541 0.0472024 0.0255561, -0.0215541 0.0472024 0.0255561, 0.016462 0.0459938 0.0284229, -0.016462 0.0459938 0.0284229, 0.0124474 0.0427235 0.0313889, -0.0124474 0.0427235 0.0313889, 0.0101215 0.0378894 0.0340026, -0.0101215 0.0378894 0.0340026, 0.0098384 0.0322276 0.035866, -0.0098384 0.0322276 0.035866, 0.0174415 0.0294527 0.0329804, -0.0174415 0.0294527 0.0329804, 0.0192939 0.0270251 0.032811, -0.0192939 0.0270251 0.032811, 0.0217926 0.0254236 0.0320726, -0.0217926 0.0254236 0.0320726, 0.0245573 0.0248921 0.0308779, -0.0245573 0.0248921 0.0308779, 0.0271671 0.0255116 0.0294086, -0.0271671 0.0255116 0.0294086, 0.0292247 0.0271877 0.0278885, -0.0292247 0.0271877 0.0278885, 0.0304167 0.0296652 0.026549, -0.0304167 0.0296652 0.026549, 0.0305618 0.0325669 0.0255939, -0.0305618 0.0325669 0.0255939, 0.0296378 0.0354512 0.0251688, -0.0296378 0.0354512 0.0251688, 0.0277855 0.0378789 0.0253383, -0.0277855 0.0378789 0.0253383, 0.0252868 0.0394803 0.0260766, -0.0252868 0.0394803 0.0260766, 0.022522 0.0400118 0.0272713, -0.022522 0.0400118 0.0272713, 0.0199123 0.0393923 0.0287406, -0.0199123 0.0393923 0.0287406, 0.0178547 0.0377163 0.0302607, -0.0178547 0.0377163 0.0302607, 0.0166627 0.0352387 0.0316003, -0.0166627 0.0352387 0.0316003, 0.0165176 0.032337 0.0325553, -0.0165176 0.032337 0.0325553
                          ]
                        }
                        coordIndex [
                          0, 32, 62, -1, 63, 33, 1, -1, 0, 62, 30, -1, 31, 63, 1, -1, 0, 2, 34, -1, 35, 3, 1, -1, 0, 34, 32, -1, 33, 35, 1, -1, 2, 4, 36, -1, 37, 5, 3, -1, 2, 36, 34, -1, 35, 37, 3, -1, 6, 8, 40, -1, 41, 9, 7, -1, 6, 40, 38, -1, 39, 41, 7, -1, 8, 10, 42, -1, 43, 11, 9, -1, 8, 42, 40, -1, 41, 43, 9, -1, 10, 12, 44, -1, 45, 13, 11, -1, 10, 44, 42, -1, 43, 45, 11, -1, 14, 16, 48, -1, 49, 17, 15, -1, 14, 48, 46, -1, 47, 49, 15, -1, 16, 18, 50, -1, 51, 19, 17, -1, 16, 50, 48, -1, 49, 51, 17, -1, 18, 20, 52, -1, 53, 21, 19, -1, 18, 52, 50, -1, 51, 53, 19, -1, 22, 24, 56, -1, 57, 25, 23, -1, 22, 56, 54, -1, 55, 57, 23, -1, 24, 26, 58, -1, 59, 27, 25, -1, 24, 58, 56, -1, 57, 59, 25, -1, 26, 28, 60, -1, 61, 29, 27, -1, 26, 60, 58, -1, 59, 61, 27, -1, 28, 30, 62, -1, 63, 31, 29, -1, 28, 62, 60, -1, 61, 63, 29, -1, 4, 6, 38, -1, 39, 7, 5, -1, 4, 38, 36, -1, 37, 39, 5, -1, 12, 14, 46, -1, 47, 15, 13, -1, 12, 46, 44, -1, 45, 47, 13, -1, 20, 22, 54, -1, 55, 23, 21, -1, 20, 54, 52, -1, 53, 55, 21, -1
                        ]
                        creaseAngle 0.2
                      }
                    }
                  ]
                  name "EyeLed"
                  color []
                  gradual TRUE
                }
                DEF DHeadLED LED {
                  rotation 1 0 0 0
                  children [
                    DEF DHeadLEDShape Shape {
                      appearance DEF DHeadLEDAppearance PBRAppearance {
                        baseColor 0.7 0.7 0.7
                        transparency 1
                        roughness 0.3
                        metalness 0
                        emissiveIntensity 6
                      }
                      geometry IndexedFaceSet {
                        coord Coordinate {
                          point [
                            0 0.0488546 0.0285779
                            0 0.057406 0.0180599
                            0.0070464 0.0573781 0.01728
                            -0.0070464 0.0573781 0.01728
                            0.0083894 0.0559858 0.019199
                            -0.0083894 0.0559858 0.019199
                            0.008978 0.0540208 0.0218855
                            -0.008978 0.0540208 0.0218855
                            0.0049843 0.051013 0.0258813
                            -0.0049843 0.051013 0.0258813
                          ]
                        }
                        coordIndex [
                          0, 8, 1, -1, 9, 0, 1, -1, 1, 8, 6, -1, 7, 9, 1, -1, 1, 6, 4, -1, 5, 7, 1, -1, 1, 4, 2, -1, 3, 5, 1, -1
                        ]
                        creaseAngle 0.2
                      }
                    }
                  ]
                  name "HeadLed"
                  color []
                  gradual TRUE
                }
              ]
              boundingObject Pose {
                translation -0.0065 0.019 -0.012
                children [
                  Box {
                    size 0.094 0.068 0.055
                  }
                ]
              }
              physics Physics {
                density -1
                mass 0.001
                centerOfMass [
                  6.39198e-05 0.0185645 0.00766662
                ]
                inertiaMatrix [
                  0.0001239683 0.00011783781 0.00011583601
                  7.8494368e-07 -7.645979e-08 1.2199205e-05
                ]
              }
              linearVelocity 2.652017562031149e-05 4.864929895557026e-05 9.952069802379726e-05
              angularVelocity -0.0001329753712150476 5.856440909507415e-05 0.0002025364224432593
            }
          }
        ]
        name "neck"
        boundingObject Pose {
          translation 0 0.013 0.0002
          children [
            Box {
              size 0.048 0.081 0.0323
            }
          ]
        }
        physics Physics {
          density -1
          mass 0.0001
          centerOfMass [
            -0.00071 0.00142 -0.01657
          ]
          inertiaMatrix [
            5.1411124e-06 8.1915737e-06 1.1379812e-05
            -5.7530255e-07 -2.4729049e-08 -1.9223094e-07
          ]
        }
        linearVelocity 3.0483046570139224e-05 4.712748702992858e-05 0.00010291483175711713
        angularVelocity -0.00013297537194526074 5.856440865890059e-05 0.000202536428488707
      }
    }
    DEF DPelvYL HingeJoint {
      jointParameters HingeJointParameters {
        position 8.576620344342512e-06
        axis 0 0 -1
        anchor 0.00025 0.0565 0
        dampingConstant 0.002
        staticFriction 0.025
      }
      device [
        RotationalMotor {
          name "PelvYL"
          acceleration 55
          maxVelocity 12.26
          minPosition -0.69
          maxPosition 2.5
          maxTorque 2.5
        }
        PositionSensor {
          name "PelvYLS"
        }
      ]
      endPoint Solid {
        translation -0.05100137278266642 0.05298443897160912 -0.23928932886798832
        rotation 0.577417862736538 0.5773972585385873 0.5772356690511184 2.0945734544463948
        children [
          DEF DPelvYLShape Pose {
            children [
              CadShape {
                url [
                  "../../TeenSizeAcrylic/Webots3d/Hip_Kiri.obj"
                ]
              }
            ]
          }
          DEF DPelvL HingeJoint {
            jointParameters HingeJointParameters {
              position -0.0005716852696286039
              axis 0 0 -1
              anchor 0.0034 0.051 0
              dampingConstant 0.002
              staticFriction 0.025
            }
            device [
              RotationalMotor {
                name "PelvL"
                acceleration 55
                maxVelocity 12.26
                minPosition -1
                maxPosition 0.93
                maxTorque 2.5
              }
              PositionSensor {
                name "PelvLS"
              }
            ]
            endPoint Solid {
              translation 2.915650276370677e-05 -1.935395798742523e-06 0
              rotation 0 0 1 0.0005716852695195754
              children [
                Pose {
                  rotation 0 0 -1 0
                  children [
                    CadShape {
                      url [
                        "../../TeenSizeAcrylic/Webots3d/Motor_Atas_Kiri.obj"
                      ]
                    }
                  ]
                }
                HingeJoint {
                  jointParameters HingeJointParameters {
                    position 0.4206165726953519
                    axis -1 0 0
                    anchor 0 0.05105 0.0501
                    dampingConstant 0.002
                    staticFriction 0.025
                  }
                  device [
                    RotationalMotor {
                      name "LegUpperL"
                      acceleration 55
                      maxVelocity 12.26
                      minPosition -0.5
                      maxPosition 1.68
                      maxTorque 2.5
                    }
                    PositionSensor {
                      name "LegUpperLS"
                    }
                  ]
                  endPoint Solid {
                    translation 0 -0.01600734725813148 0.02521175621498631
                    rotation -1 0 0 0.42061657269535185
                    children [
                      Pose {
                        rotation 1 0 0 0
                        children [
                          DEF DLegUpperLShape Group {
                            children [
                              Pose {
                                children [
                                  CadShape {
                                    url [
                                      "../../TeenSizeAcrylic/Webots3d/Femur_Kiri.obj"
                                    ]
                                  }
                                ]
                              }
                            ]
                          }
                          DEF DLegLowerL HingeJoint {
                            jointParameters HingeJointParameters {
                              position -0.6312522350663501
                              axis -1 0 0
                              anchor 0 -0.12898 0.0501
                              dampingConstant 0.002
                              staticFriction 0.025
                            }
                            device [
                              RotationalMotor {
                                name "LegLowerL"
                                acceleration 55
                                maxVelocity 12.26
                                minPosition -2.250002645680517
                                maxPosition 0.03
                                maxTorque 2.5
                              }
                              PositionSensor {
                                name "LegLowerLS"
                              }
                            ]
                            endPoint Solid {
                              translation 0 0.004710974053268202 0.0857731531643669
                              rotation 1 0 0 0.6312522350663502
                              children [
                                DEF DLegLowerLShape Pose {
                                  children [
                                    CadShape {
                                      url [
                                        "../../TeenSizeAcrylic/Webots3d/Tibia_Kiri.obj"
                                      ]
                                    }
                                  ]
                                }
                                DEF DAnkleL HingeJoint {
                                  jointParameters HingeJointParameters {
                                    position -0.34096738124830017
                                    anchor 0 -0.309 0.0501
                                    dampingConstant 0.002
                                    staticFriction 0.025
                                  }
                                  device [
                                    RotationalMotor {
                                      name "AnkleL"
                                      acceleration 55
                                      maxVelocity 12.26
                                      minPosition -2.39
                                      maxPosition 1.22
                                      maxTorque 2.5
                                    }
                                    PositionSensor {
                                      name "AnkleLS"
                                    }
                                  ]
                                  endPoint Solid {
                                    translation 0 -0.03454201772577414 -0.10044509612060959
                                    rotation -1 0 0 0.3409673812482998
                                    children [
                                      DEF DAnkleLShape Pose {
                                        children [
                                          CadShape {
                                            url [
                                              "../../TeenSizeAcrylic/Webots3d/Motor_Bawah_Kiri.obj"
                                            ]
                                          }
                                        ]
                                      }
                                      HingeJoint {
                                        jointParameters HingeJointParameters {
                                          position 3.6789661695897736e-07
                                          axis 0 0 1
                                          anchor 0.00341 -0.30896 0
                                          dampingConstant 0.002
                                          staticFriction 0.025
                                        }
                                        device [
                                          RotationalMotor {
                                            name "FootL"
                                            acceleration 55
                                            maxVelocity 12.26
                                            minPosition -1.02
                                            maxPosition 0.6
                                            maxTorque 2.5
                                          }
                                          PositionSensor {
                                            name "FootLS"
                                          }
                                        ]
                                        endPoint Solid {
                                          translation -1.1366533855588709e-07 -1.2545471328451185e-09 0.020000000000000108
                                          rotation 0 0 1 3.674277068954101e-07
                                          children [
                                            Pose {
                                              children [
                                                DEF LEFT_FOOT_SLOT Group {
                                                }
                                                DEF DFootLShape Group {
                                                  children [
                                                    Pose {
                                                      children [
                                                        CadShape {
                                                          url [
                                                            "../../TeenSizeAcrylic/Webots3d/Foot_Kiri.obj"
                                                          ]
                                                        }
                                                      ]
                                                    }
                                                  ]
                                                }
                                              ]
                                            }
                                          ]
                                          boundingObject Group {
                                            children [
                                              Pose {
                                                translation 0.0134 -0.34846 0.0402
                                                children [
                                                  Box {
                                                    size 0.1 0.005 0.18
                                                  }
                                                ]
                                              }
                                            ]
                                          }
                                          physics Physics {
                                            density -1
                                            mass 0.221488
                                          }
                                          linearVelocity 6.979534350584176e-06 2.2663483122441612e-05 0.00011689908017076007
                                          angularVelocity 5.021791224457145e-05 4.692494788021178e-05 0.00012573582024363742
                                        }
                                      }
                                    ]
                                    name "solid(1)"
                                    boundingObject Group {
                                      children [
                                        Pose {
                                          translation 0.00345 -0.2884 0.02418
                                          children [
                                            Box {
                                              size 0.044 0.07 0.098
                                            }
                                          ]
                                        }
                                      ]
                                    }
                                    physics Physics {
                                      density -1
                                      mass 0.221488
                                    }
                                    linearVelocity 1.3324489437543266e-05 2.2986237674001617e-05 0.00011395277915760479
                                    angularVelocity 4.999506757330902e-05 4.74829134951275e-05 0.00012618316770275184
                                  }
                                }
                              ]
                              boundingObject Group {
                                children [
                                  Pose {
                                    translation 0.0049 -0.2189 0.05
                                    rotation 1 0 0 0
                                    children [
                                      Box {
                                        size 0.059 0.213 0.05
                                      }
                                    ]
                                  }
                                ]
                              }
                              physics Physics {
                                density -1
                                mass 0.095376
                                centerOfMass [
                                  -0.000592469 -0.0539545 0.00654763
                                ]
                                inertiaMatrix [
                                  9.3369608e-05 4.6295534e-05 0.00011351516
                                  -9.3567395e-07 -2.3992085e-07 -1.2858493e-05
                                ]
                              }
                              linearVelocity 1.6125577878630052e-05 8.058408968632237e-06 0.00011577681265491974
                              angularVelocity 4.937488969308275e-05 4.719595603504349e-05 0.00012815542939217023
                            }
                          }
                        ]
                      }
                    ]
                    boundingObject Pose {
                      translation 0.0049 -0.0387 0.0501
                      rotation 1 0 0 0
                      children [
                        Box {
                          size 0.059 0.207 0.046
                        }
                      ]
                    }
                    physics Physics {
                      density -1
                      mass 0.1357538
                    }
                    linearVelocity 1.7605124955906802e-05 8.085910121333562e-06 0.0001151323461987636
                    angularVelocity 5.0894583101901634e-05 4.787630038412265e-05 0.00012519892157824406
                  }
                }
              ]
              name "solid(1)"
              boundingObject Group {
                children [
                  Pose {
                    translation 0.00347 0.03045 0.0241
                    children [
                      Box {
                        size 0.044 0.07 0.098
                      }
                    ]
                  }
                ]
              }
              physics Physics {
                density -1
                mass 0.1357538
              }
              linearVelocity 2.811734264045188e-05 5.606503899542349e-06 0.00011519454313312147
              angularVelocity -9.439017711203112e-05 -2.2121675888581933e-05 0.00012774636136564526
            }
          }
        ]
        name "pelvYL"
        boundingObject Group {
          children [
            Pose {
              translation 0.0034 0.0601 0.05118
              children [
                Box {
                  size 0.0306 0.0458 0.054
                }
              ]
            }
          ]
        }
        physics Physics {
          density -1
          mass 0.1774664
        }
        linearVelocity 2.4689308350124463e-05 6.930959393510555e-06 0.00011212857696583552
        angularVelocity -0.00012836471951633096 4.8668158339775044e-05 0.00011791855556698512
      }
    }
    DEF DPelvYR HingeJoint {
      jointParameters HingeJointParameters {
        position 6.2060575903236905e-06
        axis 0 0 -1
        anchor 0.00025 -0.0565 0
        dampingConstant 0.002
        staticFriction 0.025
      }
      device [
        RotationalMotor {
          name "PelvYR"
          acceleration 55
          maxVelocity 12.26
          minPosition -2.42
          maxPosition 0.66
          maxTorque 2.5
        }
        PositionSensor {
          name "PelvYRS"
        }
      ]
      endPoint Solid {
        translation -0.050894219278942956 -0.05988381368158505 -0.23928791782742848
        rotation 0.5772844829182501 0.5773160504491036 0.5774502607806637 2.0943022998708054
        children [
          DEF DPelvYRShape Pose {
            children [
              CadShape {
                url [
                  "../../TeenSizeAcrylic/Webots3d/Hip_Kanan.obj"
                ]
              }
            ]
          }
          DEF DPelvR HingeJoint {
            jointParameters HingeJointParameters {
              position 2.471303026298048e-06
              axis 0 0 -1
              anchor 0.0034 0.051 0
              dampingConstant 0.002
              staticFriction 0.025
            }
            device [
              PositionSensor {
                name "PelvRS"
              }
              RotationalMotor {
                name "PelvR"
                acceleration 55
                maxVelocity 12.26
                minPosition -1.01
                maxPosition 1.01
                maxTorque 2.5
              }
            ]
            endPoint Solid {
              translation -1.2603644390261556e-07 8.402586820777103e-09 0
              rotation 0 0 -1 2.4712577392612932e-06
              children [
                Pose {
                  children [
                    DEF DPelvRShape CadShape {
                      url [
                        "../../TeenSizeAcrylic/Webots3d/Motor_Atas_Kanan.obj"
                      ]
                    }
                  ]
                }
                HingeJoint {
                  jointParameters HingeJointParameters {
                    position -0.4208364535177459
                    anchor 0 0.051 0.0501
                    dampingConstant 0.002
                    staticFriction 0.025
                  }
                  device [
                    PositionSensor {
                      name "LegUpperRS"
                    }
                    RotationalMotor {
                      name "LegUpperR"
                      acceleration 55
                      maxVelocity 12.26
                      minPosition -1.77
                      maxPosition 0.45
                      maxTorque 2.5
                    }
                  ]
                  endPoint Solid {
                    translation 0 -0.016017180707157012 0.02520607523783371
                    rotation -1 0 0 0.4208364535177462
                    children [
                      Pose {
                        rotation 1 0 0 0
                        children [
                          DEF DLegUpperRShape Group {
                            children [
                              Pose {
                                children [
                                  CadShape {
                                    url [
                                      "../../TeenSizeAcrylic/Webots3d/Femur_Kanan.obj"
                                    ]
                                  }
                                ]
                              }
                            ]
                          }
                          DEF DLegLowerR HingeJoint {
                            jointParameters HingeJointParameters {
                              position 0.6312500471829702
                              anchor 0 -0.129 0.0501
                              dampingConstant 0.002
                              staticFriction 0.025
                            }
                            device [
                              RotationalMotor {
                                name "LegLowerR"
                                acceleration 55
                                maxVelocity 12.26
                                minPosition -0.02
                                maxPosition 2.2500008467517643
                                maxTorque 2.5
                              }
                              PositionSensor {
                                name "LegLowerRS"
                              }
                            ]
                            endPoint Solid {
                              translation 0 0.004707197910016725 0.08578466375141924
                              rotation 1 0 0 0.6312500471829701
                              children [
                                DEF DLegLowerRShape Pose {
                                  children [
                                    CadShape {
                                      url [
                                        "../../TeenSizeAcrylic/Webots3d/Tibia_Kanan.obj"
                                      ]
                                    }
                                  ]
                                }
                                DEF DAnkleR HingeJoint {
                                  jointParameters HingeJointParameters {
                                    position 0.34096795698740423
                                    axis -1 0 0
                                    anchor 0 -0.309 0.0501
                                    dampingConstant 0.002
                                    staticFriction 0.025
                                  }
                                  device [
                                    RotationalMotor {
                                      name "AnkleR"
                                      acceleration 55
                                      maxVelocity 12.26
                                      minPosition -1.24
                                      maxPosition 1.88
                                      maxTorque 2.5
                                    }
                                    PositionSensor {
                                      name "AnkleRS"
                                    }
                                  ]
                                  endPoint Solid {
                                    translation 0 -0.034542104400516915 -0.10044525413677749
                                    rotation -1 0 0 0.34096795698740423
                                    children [
                                      DEF DAnkleRShape Pose {
                                        children [
                                          CadShape {
                                            url [
                                              "../../TeenSizeAcrylic/Webots3d/Motor_Bawah_Kanan.obj"
                                            ]
                                          }
                                        ]
                                      }
                                      HingeJoint {
                                        jointParameters HingeJointParameters {
                                          position -3.1260282945012874e-07
                                          axis 0 0 1
                                          anchor 0.0034 -0.309 0
                                          dampingConstant 0.002
                                          staticFriction 0.025
                                        }
                                        device [
                                          RotationalMotor {
                                            name "FootR"
                                            acceleration 55
                                            maxVelocity 12.26
                                            minPosition -0.68
                                            maxPosition 1.04
                                            maxTorque 2.5
                                          }
                                          PositionSensor {
                                            name "FootRS"
                                          }
                                        ]
                                        endPoint Solid {
                                          translation 9.659427446925481e-08 1.062833931975149e-09 0.019999999999999952
                                          rotation 0 0 -1 3.1256939416234273e-07
                                          children [
                                            Pose {
                                              children [
                                                DEF RIGHT_FOOT_SLOT Group {
                                                }
                                                DEF DFootRShape Group {
                                                  children [
                                                    Pose {
                                                      children [
                                                        CadShape {
                                                          url [
                                                            "../../TeenSizeAcrylic/Webots3d/FootKanan.obj"
                                                          ]
                                                        }
                                                      ]
                                                    }
                                                  ]
                                                }
                                              ]
                                            }
                                          ]
                                          boundingObject Group {
                                            children [
                                              Pose {
                                                translation -0.00659 -0.3485 0.0402
                                                children [
                                                  Box {
                                                    size 0.1 0.005 0.18
                                                  }
                                                ]
                                              }
                                            ]
                                          }
                                          physics Physics {
                                            density -1
                                            mass 0.221488
                                          }
                                          linearVelocity -6.739747639904383e-06 -2.1746805691972823e-05 0.00011039730430477713
                                          angularVelocity -0.0001278540325125204 4.840708946344575e-05 9.320578665194473e-05
                                        }
                                      }
                                    ]
                                    name "solid(1)"
                                    boundingObject Group {
                                      children [
                                        Pose {
                                          translation 0.0034 -0.2885 0.02418
                                          children [
                                            Box {
                                              size 0.044 0.07 0.098
                                            }
                                          ]
                                        }
                                      ]
                                    }
                                    physics Physics {
                                      density -1
                                      mass 0.221488
                                    }
                                    linearVelocity -3.773305148285542e-07 -1.3705513063293324e-05 0.0001142842184678967
                                    angularVelocity -0.00012813443229398665 4.9055111243051084e-05 9.27026060366149e-05
                                  }
                                }
                              ]
                              boundingObject Group {
                                children [
                                  Pose {
                                    translation 0.0019 -0.219 0.05
                                    rotation 1 0 0 0
                                    children [
                                      Box {
                                        size 0.059 0.213 0.05
                                      }
                                    ]
                                  }
                                ]
                              }
                              physics Physics {
                                density -1
                                mass 0.095376
                                centerOfMass [
                                  0.000592469 -0.0539545 0.00654763
                                ]
                                inertiaMatrix [
                                  9.3369608e-05 4.6295534e-05 0.00011351516
                                  9.3567395e-07 2.3992085e-07 -1.2858493e-05
                                ]
                              }
                              linearVelocity 6.803873850988436e-06 1.2018762980451238e-05 0.00010042560860202789
                              angularVelocity -0.0001264009147008409 4.950434647728523e-05 8.536696106133389e-05
                            }
                          }
                        ]
                      }
                    ]
                    boundingObject Group {
                      children [
                        Pose {
                          translation 0.0019 -0.039 0.05
                          rotation 1 0 0 0
                          children [
                            Box {
                              size 0.059 0.207 0.046
                            }
                          ]
                        }
                      ]
                    }
                    physics Physics {
                      density -1
                      mass 0.1357538
                    }
                    linearVelocity 7.668590353980462e-06 1.3830749465078612e-05 0.00010074899008450908
                    angularVelocity -0.00013025123394462597 4.612264146760644e-05 0.00010158191147363238
                  }
                }
              ]
              boundingObject Group {
                children [
                  Pose {
                    translation 0.0034 0.0304 0.0241
                    children [
                      Box {
                        size 0.044 0.07 0.098
                      }
                    ]
                  }
                ]
              }
              physics Physics {
                density -1
                mass 0.1357538
              }
              linearVelocity 1.5525159350611073e-05 2.6029565967999962e-05 0.00010287639995386887
              angularVelocity -0.00012668284458044318 4.59810732995954e-05 9.140987754638342e-05
            }
          }
        ]
        name "pelvYR"
        boundingObject Group {
          children [
            Pose {
              translation 0.0034 0.0601 0.0511
              children [
                Box {
                  size 0.0306 0.0458 0.054
                }
              ]
            }
          ]
        }
        physics Physics {
          density -1
          mass 0.1774664
        }
        linearVelocity 1.4164829699172272e-05 2.782624577509554e-05 9.971953159962047e-05
        angularVelocity -0.00012636232136359587 4.5389195892114394e-05 9.107709174742014e-05
      }
    }
    DEF DShoulderL HingeJoint {
      jointParameters HingeJointParameters {
        position 0.7218675774186541
        axis 0 1 0
        anchor 0.0003 0 -0.0022
        dampingConstant 0.002
        staticFriction 0.025
      }
      device [
        RotationalMotor {
          name "ShoulderL"
          acceleration 55
          maxVelocity 12.26
          minPosition -3.14
          maxPosition 2.85
          maxTorque 2.5
        }
        PositionSensor {
          name "ShoulderLS"
        }
      ]
      endPoint Solid {
        translation 0.0008695032504883609 0.11819999848932343 -0.0024380543572451144
        rotation 0.6735484801321291 0.6735532090030903 0.30439861949972485 2.550635041883305
        children [
          DEF DShoulderLShape Pose {
            translation 0.1332 -0.1339 -0.083
            children [
              CadShape {
                url [
                  "../../TeenSizeAcrylic/Webots3d/Bahu_Kiri.obj"
                ]
              }
            ]
          }
          DEF DArmUpperL HingeJoint {
            jointParameters HingeJointParameters {
              position 0.30717796538009196
              axis 0 0 -1
              anchor 0.0158 -0.0002 0
              dampingConstant 0.002
              staticFriction 0.025
            }
            device [
              RotationalMotor {
                name "ArmUpperL"
                acceleration 55
                maxVelocity 12.26
                minPosition -2.25
                maxPosition 1.77
                maxTorque 2.5
              }
              PositionSensor {
                name "ArmUpperLS"
              }
            ]
            endPoint Solid {
              translation 0.006685404555743265 0.010185167451178919 0.00010979981288155968
              rotation -1.3225699634759133e-05 -1.8449740718446873e-06 0.9999999999108385 0.478222556633342
              children [
                DEF DArmUpperLShape Group {
                  children [
                    Pose {
                      translation 0.1207 -0.1471 -0.0831
                      children [
                        CadShape {
                          url [
                            "../../TeenSizeAcrylic/Webots3d/Lengan_Atas_Kiri.obj"
                          ]
                        }
                      ]
                    }
                  ]
                }
                DEF DArmLowerL HingeJoint {
                  jointParameters HingeJointParameters {
                    position -0.5160588753344353
                    anchor 0 -0.20344 0.0053
                    dampingConstant 0.002
                    staticFriction 0.025
                  }
                  device [
                    RotationalMotor {
                      name "ArmLowerL"
                      acceleration 55
                      maxVelocity 12.26
                      minPosition -1.18
                      maxPosition 1.63
                      maxTorque 2.5
                    }
                    PositionSensor {
                      name "ArmLowerLS"
                    }
                  ]
                  endPoint Solid {
                    translation 0 -0.07531388219869031 0.0012476504142727588
                    rotation -0.9999999999999996 2.830041842451854e-08 -1.1410807692507506e-08 2.0868585636404355
                    children [
                      DEF LEFT_HAND_SLOT Group {
                      }
                      DEF DArmLowerLShape Group {
                        children [
                          Pose {
                            translation 0.1207 0.111 -0.2019
                            children [
                              CadShape {
                                url [
                                  "../../TeenSizeAcrylic/Webots3d/Lengan_Bawah_Kiri.obj"
                                ]
                              }
                            ]
                          }
                        ]
                      }
                    ]
                    boundingObject Pose {
                      translation 0.0016 -0.0348 -0.1134
                      children [
                        Box {
                          size 0.0465 0.208 0.04
                        }
                      ]
                    }
                    physics Physics {
                      density -1
                      mass 0.0592885
                      centerOfMass [
                        0.003 -0.05 -0.0112
                      ]
                      inertiaMatrix [
                        8.6855267e-05 2.1192085e-05 8.684545e-05
                        5.3020311e-06 4.3636051e-07 -6.4855932e-06
                      ]
                    }
                    linearVelocity 3.621286527632059e-05 7.756277519517273e-07 0.00012617958210525454
                    angularVelocity -0.00014094566629903733 5.5574093025368774e-05 0.00020650519922938836
                  }
                }
              ]
              boundingObject Group {
                children [
                  Pose {
                    translation 0.0034 -0.08 -0.002
                    children [
                      Box {
                        size 0.04 0.162 0.0455
                      }
                    ]
                  }
                  Pose {
                    translation 0.0034 -0.1909 0.0053
                    rotation 0 1 0 1.5708
                    children [
                      Box {
                        size 0.0333 0.055 0.059
                      }
                    ]
                  }
                ]
              }
              physics Physics {
                density -1
                mass 0.168377
                centerOfMass [
                  0.000659787 -0.036239 0.000734065
                ]
                inertiaMatrix [
                  0.00012202839 3.8088441e-05 0.0001134083
                  -2.0812626e-06 -8.8143449e-07 1.8251448e-06
                ]
              }
              linearVelocity 4.0330966358794264e-05 1.3617981785690949e-05 0.0001214676237758956
              angularVelocity -0.00014094552374108773 5.557411793714472e-05 0.00020650513956387053
            }
          }
        ]
        name "shoulderL"
        boundingObject Pose {
          translation 0.0033 -0.0002 -0.0006
          children [
            Box {
              size 0.055 0.0333 0.059
            }
          ]
        }
        physics Physics {
          density -1
          mass 0.025913
          centerOfMass [
            0.00139 -0.01352 0.01264
          ]
          inertiaMatrix [
            9.7758165e-06 1.0511104e-05 5.476798e-06
            1.6911839e-06 -4.5174329e-07 3.3406955e-07
          ]
        }
        linearVelocity 3.594243075746478e-05 1.4699220957199612e-05 0.00011780648347542411
        angularVelocity -0.00014094589374837702 5.557405970295176e-05 0.00020650523969970366
      }
    }
    DEF DShoulderR HingeJoint {
      jointParameters HingeJointParameters {
        position -0.8447398406803073
        axis 0 -1 0
        anchor 0.00028 0 -0.0023
        dampingConstant 0.002
        staticFriction 0.025
      }
      device [
        RotationalMotor {
          name "ShoulderR"
          acceleration 55
          maxVelocity 12.26
          minPosition -3.14
          maxPosition 3.14
          maxTorque 2.5
        }
        PositionSensor {
          name "ShoulderRS"
        }
      ]
      endPoint Solid {
        translation 0.007009125982262389 -0.125300310166984 0.003178984731734522
        rotation 0.6828998957369725 0.6828941122451843 0.25942891871048934 2.6340369525127385
        children [
          DEF DShoulderRShape Pose {
            translation 0.10866 -0.1424 -0.0828
            children [
              CadShape {
                url [
                  "../../TeenSizeAcrylic/Webots3d/Bahu_Kanan.obj"
                ]
              }
            ]
          }
          DEF DArmUpperR HingeJoint {
            jointParameters HingeJointParameters {
              position -0.3117856599962248
              axis 0 0 -1
              anchor -0.0087 -0.00875 0
              dampingConstant 0.002
              staticFriction 0.025
            }
            device [
              RotationalMotor {
                name "ArmUpperR"
                acceleration 55
                maxVelocity 12.26
                minPosition -1.68
                maxPosition 2.3
                maxTorque 2.5
              }
              PositionSensor {
                name "ArmUpperRS"
              }
            ]
            endPoint Solid {
              translation -0.010633832825004682 -0.007639688960275363 -0.0016499999999999423
              rotation 0 0 -1 0.473614646104027
              children [
                DEF DArmUpperRShape Pose {
                  translation 0.1196 -0.1338 -0.0811
                  children [
                    CadShape {
                      url [
                        "../../TeenSizeAcrylic/Webots3d/Lengan_Atas_Kanan.obj"
                      ]
                    }
                  ]
                }
                DEF DArmLowerR HingeJoint {
                  jointParameters HingeJointParameters {
                    position 0.5114512527554803
                    axis -1 0 0
                    anchor 0 -0.1901 0.0073
                    dampingConstant 0.002
                    staticFriction 0.025
                  }
                  device [
                    RotationalMotor {
                      name "ArmLowerR"
                      acceleration 55
                      maxVelocity 12.26
                      minPosition -1.65
                      maxPosition 1.16
                      maxTorque 2.5
                    }
                    PositionSensor {
                      name "ArmLowerRS"
                    }
                  ]
                  endPoint Solid {
                    translation -0.010000000000000012 -0.14030714586286733 -0.03188509508573681
                    rotation -0.9999999999999967 5.7358765478650244e-08 5.5328776731365245e-08 2.0822509537974465
                    children [
                      DEF RIGHT_HAND_SLOT Group {
                      }
                      DEF DArmLowerRShape Group {
                        children [
                          Pose {
                            translation 0.1296 0.0415 -0.151
                            children [
                              CadShape {
                                url [
                                  "../../TeenSizeAcrylic/Webots3d/Lengan_Bawah_Kanan.obj"
                                ]
                              }
                            ]
                          }
                        ]
                      }
                    ]
                    boundingObject Pose {
                      translation 0.0134 -0.104 -0.0625
                      children [
                        Box {
                          size 0.0465 0.208 0.04
                        }
                      ]
                    }
                    physics Physics {
                      density -1
                      mass 0.0592885
                      centerOfMass [
                        -0.00666564 -0.0458382 -0.0134901
                      ]
                      inertiaMatrix [
                        8.6855267e-05 2.1192085e-05 8.684545e-05
                        -5.3020311e-06 -4.3636051e-07 -6.4855932e-06
                      ]
                    }
                    linearVelocity 1.1635915780131208e-05 8.160020961983972e-05 9.297329653424496e-05
                    angularVelocity -0.00012590254963699683 6.307887947994038e-05 0.0001986384123189065
                  }
                }
              ]
              boundingObject Group {
                children [
                  Pose {
                    translation 0.0022 -0.0665 -0.0001
                    children [
                      Box {
                        size 0.04 0.162 0.0455
                      }
                    ]
                  }
                  Pose {
                    translation 0.0022 -0.1775 0.0074
                    rotation 0 1 0 1.5708
                    children [
                      Box {
                        size 0.0333 0.055 0.059
                      }
                    ]
                  }
                ]
              }
              physics Physics {
                density -1
                mass 0.168377
                centerOfMass [
                  -0.000659787 -0.036239 0.000734065
                ]
                inertiaMatrix [
                  0.00012202839 3.8088441e-05 0.0001134083
                  2.0812626e-06 8.8143449e-07 1.8251448e-06
                ]
              }
              linearVelocity 1.335135525105075e-05 6.85290277422876e-05 8.92927588053381e-05
              angularVelocity -0.00012590255859595595 6.307890431752768e-05 0.00019863838465895777
            }
          }
        ]
        name "shoulderR"
        boundingObject Pose {
          translation 0.0038 -0.00865 -0.0004
          rotation 0 0 -1 0
          children [
            Box {
              size 0.055 0.0333 0.059
            }
          ]
        }
        physics Physics {
          density -1
          mass 0.025913
          centerOfMass [
            0.00139 0.01352 0.01024
          ]
          inertiaMatrix [
            9.7758165e-06 1.0511104e-05 5.476798e-06
            -1.6911839e-06 4.5174329e-07 3.3406955e-07
          ]
        }
        linearVelocity 1.0804626477699554e-05 5.716886744214275e-05 8.639939141951312e-05
        angularVelocity -0.00012590236442335993 6.30789941325603e-05 0.00019863860539017246
      }
    }
    DEF DHeadBackLED Pose {
      translation -0.043 -0.01 -0.01
      rotation 0.577416935887098 0.5773169329539689 0.5773169329539689 2.0944
      children [
        Shape {
          appearance PBRAppearance {
            baseColor 0.7 0.7 0.7
            roughness 0.3
            metalness 0
            emissiveIntensity 6
          }
          geometry Box {
            size 0.002 0.005 0.002
          }
        }
      ]
    }
    DEF DEyeBackLED Pose {
      translation -0.043 -0.015 -0.01
      rotation 0.577416935887098 0.5773169329539689 0.5773169329539689 2.0944
      children [
        Shape {
          appearance PBRAppearance {
            baseColor 0.7 0.7 0.7
            roughness 0.3
            metalness 0
            emissiveIntensity 6
          }
          geometry Box {
            size 0.002 0.005 0.002
          }
        }
      ]
    }
  ]
  name "Pororo"
  model "Pororo"
  description "Robot Pororo by Rico Agustiawan"
  boundingObject Group {
    children [
      Pose {
        translation -0.013 0 -0.0667
        rotation 0.577416935887098 0.5773169329539689 0.5773169329539689 2.0944
        children [
          Box {
            size 0.18 0.173 0.1
          }
        ]
      }
    ]
  }
  physics Physics {
    density -1
    mass 0.0001
    centerOfMass [
      -0.05 0 -0.08
    ]
    inertiaMatrix [
      0.00310818 0.0063787776 0.0053316425
      -0.00025460189 0.0020318174 0.00016417863
    ]
  }
  controller "enum"
  linearVelocity 3.2301275361912296e-05 3.455365137239319e-05 0.0001086555587740956
  angularVelocity -0.00013297537350564218 5.856440698680144e-05 0.0002025364356037452
}
